<?xml version="1.0" ?>
<!-- =================================================================================== -->
<!-- |    This document was autogenerated by xacro from UR5_gripper2.xacro             | -->
<!-- |    EDITING THIS FILE BY HAND IS NOT RECOMMENDED                                 | -->
<!-- =================================================================================== -->
<robot name="ur5">

  <!-- ===================================================================  -->
  <!--                       UR5 ROBOT DESCRIPTION                          -->
  <!-- ===================================================================  -->
  <link name="stand">
    <visual>
      <origin rpy="0 0 0" xyz="0. 0.0 0.0"/>
      <geometry>
        <mesh filename="package://ur5controller/arm/meshes/visual/arm_stand.obj"/>
      </geometry>
      <material name="blau">
        <color rgba="0.3 0.43 0.512 1.0"/>
      </material>
    </visual>
    <collision>
      <geometry>
        <mesh filename="package://ur5controller/arm/meshes/visual/arm_stand.obj"/>
      </geometry>
    </collision>
    <inertial>
      <mass value="4.0"/>
      <origin rpy="0 0 0" xyz="0.0 0.0 0.0"/>
      <inertia ixx="0.00443333156" ixy="0.0" ixz="0.0" iyy="0.00443333156" iyz="0.0" izz="0.0072"/>
    </inertial>
  </link>

  <joint name="stand_joints" type="fixed">
    <parent link="stand"/>
    <child link="base_link"/>
    <origin rpy="0.0 0.0 0.0" xyz="0.0 0.0 0.5"/>
    <axis xyz="0 0 1"/>
    <limit effort="2250.0" lower="-6.26573" upper="6.26573" velocity="3.15"/>
    <dynamics damping="0.1" friction="10.0"/>
  </joint>


  <link name="base_link">
    <visual>
      <geometry>
        <mesh filename="package://ur5controller/arm/meshes/visual/base.obj"/>
      </geometry>
      <material name="Scheibe">
        <color rgba="0.07 0.07 0.07 1.0"/>
      </material>
    </visual>
    <collision>
      <geometry>
        <mesh filename="package://ur5controller/arm/meshes/collision/base.stl"/>
      </geometry>
    </collision>
    <inertial>
      <mass value="4.0"/>
      <origin rpy="0 0 0" xyz="0.0 0.0 0.0"/>
      <inertia ixx="0.00443333156" ixy="0.0" ixz="0.0" iyy="0.00443333156" iyz="0.0" izz="0.0072"/>
    </inertial>
  </link>


  <joint name="shoulder_pan_joint" type="revolute">
    <parent link="base_link"/>
    <child link="shoulder_link"/>
    <origin rpy="0.0 0.0 0.0" xyz="0.0 0.0 0.089159"/>
    <axis xyz="0 0 1"/>
    <limit effort="2250.0" lower="-6.26573" upper="6.26573" velocity="3.15"/>
    <dynamics damping="0.1" friction="10.0"/>
  </joint>


  <link name="shoulder_link">
    <visual>
      <geometry>
        <mesh filename="package://ur5controller/arm/meshes/visual/shoulder.obj"/>
      </geometry>
      <material name="blau">
        <color rgba="0.3 0.43 0.512 1.0"/>
      </material>
    </visual>
    <collision>
      <geometry>
        <mesh filename="package://ur5controller/arm/meshes/collision/shoulder.stl"/>
      </geometry>
    </collision>
    <inertial>
      <mass value="3.7"/>
      <origin rpy="0 0 0" xyz="0.0 0.0 0.0"/>
      <inertia ixx="0.010267495893" ixy="0.0" ixz="0.0" iyy="0.010267495893" iyz="0.0" izz="0.00666"/>
    </inertial>
  </link>


  <joint name="shoulder_lift_joint" type="revolute">
    <parent link="shoulder_link"/>
    <child link="upper_arm_link"/>
    <origin rpy="0.0 1.570796325 0.0" xyz="0.0 0.13585 0.0"/>
    <axis xyz="0 1 0"/>
    <limit effort="2250.0" lower="-6.26573" upper="6.26573" velocity="3.15"/>
    <dynamics damping="0.1" friction="10.0"/>
  </joint>


  <link name="upper_arm_link">
    <visual>
      <geometry>
        <mesh filename="package://ur5controller/arm/meshes/visual/upperarm.obj"/>
      </geometry>
      <material name="blau">
        <color rgba="0.3 0.43 0.512 1.0"/>
      </material>
    </visual>
    <collision>
      <geometry>
        <mesh filename="package://ur5controller/arm/meshes/collision/upperarm.stl"/>
      </geometry>
    </collision>
    <inertial>
      <mass value="8.393"/>
      <origin rpy="0 0 0" xyz="0.0 0.0 0.28"/>
      <inertia ixx="0.22689067591" ixy="0.0" ixz="0.0" iyy="0.22689067591" iyz="0.0" izz="0.0151074"/>
    </inertial>
  </link>


  <joint name="elbow_joint" type="revolute">
    <parent link="upper_arm_link"/>
    <child link="forearm_link"/>
    <origin rpy="0.0 0.0 0.0" xyz="0.0 -0.1197 0.425"/>
    <axis xyz="0 1 0"/>
    <!-- FIXME these efforts are multiplie by 20 for fast training. Should just switch to fast robot -->
    <limit effort="2250.0" lower="-6.26573" upper="6.26573" velocity="3.15"/>
    <dynamics damping="0.1" friction="10.0"/>
  </joint>


  <link name="forearm_link">
    <visual>
      <geometry>
        <mesh filename="package://ur5controller/arm/meshes/visual/forearm.obj"/>
      </geometry>
      <material name="blau">
        <color rgba="0.3 0.43 0.512 1.0"/>
      </material>
    </visual>
    <collision>
      <geometry>
        <mesh filename="package://ur5controller/arm/meshes/collision/forearm.stl"/>
      </geometry>
    </collision>
    <inertial>
      <mass value="2.275"/>
      <origin rpy="0 0 0" xyz="0.0 0.0 0.25"/>
      <inertia ixx="0.049443313556" ixy="0.0" ixz="0.0" iyy="0.049443313556" iyz="0.0" izz="0.004095"/>
    </inertial>
  </link>


  <joint name="wrist_1_joint" type="revolute">
    <parent link="forearm_link"/>
    <child link="wrist_1_link"/>
    <origin rpy="0.0 1.570796325 0.0" xyz="0.0 0.0 0.39225"/>
    <axis xyz="0 1 0"/>
    <limit effort="420.0" lower="-6.26573" upper="6.26573" velocity="3.2"/>
    <dynamics damping="0.1" friction="10.0"/>
  </joint>


  <link name="wrist_1_link">
    <visual>
      <geometry>
        <mesh filename="package://ur5controller/arm/meshes/visual/wrist1.obj"/>
      </geometry>
      <material name="blau">
        <color rgba="0.3 0.43 0.512 1.0"/>
      </material>
    </visual>
    <collision>
      <geometry>
        <mesh filename="package://ur5controller/arm/meshes/collision/wrist1.stl"/>
      </geometry>
    </collision>
    <inertial>
      <mass value="1.219"/>
      <origin rpy="0 0 0" xyz="0.0 0.0 0.0"/>
      <inertia ixx="0.111172755531" ixy="0.0" ixz="0.0" iyy="0.111172755531" iyz="0.0" izz="0.21942"/>
    </inertial>
  </link>


  <joint name="wrist_2_joint" type="revolute">
    <parent link="wrist_1_link"/>
    <child link="wrist_2_link"/>
    <origin rpy="0.0 0.0 0.0" xyz="0.0 0.093 0.0"/>
    <axis xyz="0 0 1"/>
    <limit effort="420.0" lower="-6.26573" upper="6.26573" velocity="3.2"/>
    <dynamics damping="0.1" friction="10.0"/>
  </joint>


  <link name="wrist_2_link">
    <visual>
      <geometry>
        <mesh filename="package://ur5controller/arm/meshes/visual/wrist2.obj"/>
      </geometry>
      <material name="blau">
        <color rgba="0.3 0.43 0.512 1.0"/>
      </material>
    </visual>
    <collision>
      <geometry>
        <mesh filename="package://ur5controller/arm/meshes/collision/wrist2.stl"/>
      </geometry>
    </collision>
    <inertial>
      <mass value="1.219"/>
      <origin rpy="0 0 0" xyz="0.0 0.0 0.0"/>
      <inertia ixx="0.111172755531" ixy="0.0" ixz="0.0" iyy="0.111172755531" iyz="0.0" izz="0.21942"/>
    </inertial>
  </link>


  <joint name="wrist_3_joint" type="revolute">
    <parent link="wrist_2_link"/>
    <child link="wrist_3_link"/>
    <origin rpy="0.0 0.0 0.0" xyz="0.0 0.0 0.09465"/>
    <axis xyz="0 1 0"/>
    <limit effort="420.0" lower="-6.26573" upper="6.26573" velocity="3.2"/>
    <dynamics damping="0.1" friction="10.0"/>
  </joint>


  <link name="wrist_3_link">
    <visual>
      <geometry>
        <mesh filename="package://ur5controller/arm/meshes/visual/wrist3.obj"/>
      </geometry>
      <material name="Scheibe">
        <color rgba="0.07 0.07 0.07 1.0"/>
      </material>
    </visual>
    <collision>
      <geometry>
        <mesh filename="package://ur5controller/arm/meshes/collision/wrist3.stl"/>
      </geometry>
    </collision>
    <inertial>
      <mass value="0.1879"/>
      <origin rpy="0 0 0" xyz="0.0 0.0 0.0"/>
      <inertia ixx="0.0171364731454" ixy="0.0" ixz="0.0" iyy="0.0171364731454" iyz="0.0" izz="0.033822"/>
    </inertial>
  </link>


  <joint name="ee_fixed_joint" type="fixed">
    <parent link="wrist_3_link"/>
    <child link="ee_link0"/>
    <origin rpy="0.0 0.0 1.570796325" xyz="0.0 0.08 0.0"/>
  </joint>


  <link name="ee_link0">
    <inertial>
      <mass value="0.018"/>
      <inertia ixx="8.82e-6" ixy="0" ixz="0" iyy="8.82e-6" iyz="0" izz="8.82e-6" />
    </inertial>
    <collision>
      <geometry>
        <box size="0.01 0.01 0.01"/>
      </geometry>
      <origin rpy="0 0 0" xyz="-0.01 0 0"/>
    </collision>
  </link>


  <transmission name="shoulder_pan_trans">
    <type>transmission_interface/SimpleTransmission</type>
    <joint name="shoulder_pan_joint">
      <hardwareInterface>PositionJointInterface</hardwareInterface>
    </joint>
    <actuator name="shoulder_pan_motor">
      <mechanicalReduction>1</mechanicalReduction>
    </actuator>
  </transmission>


  <transmission name="shoulder_lift_trans">
    <type>transmission_interface/SimpleTransmission</type>
    <joint name="shoulder_lift_joint">
      <hardwareInterface>PositionJointInterface</hardwareInterface>
    </joint>
    <actuator name="shoulder_lift_motor">
      <mechanicalReduction>1</mechanicalReduction>
    </actuator>
  </transmission>


  <transmission name="elbow_trans">
    <type>transmission_interface/SimpleTransmission</type>
    <joint name="elbow_joint">
      <hardwareInterface>PositionJointInterface</hardwareInterface>
    </joint>
    <actuator name="elbow_motor">
      <mechanicalReduction>1</mechanicalReduction>
    </actuator>
  </transmission>


  <transmission name="wrist_1_trans">
    <type>transmission_interface/SimpleTransmission</type>
    <joint name="wrist_1_joint">
      <hardwareInterface>PositionJointInterface</hardwareInterface>
    </joint>
    <actuator name="wrist_1_motor">
      <mechanicalReduction>1</mechanicalReduction>
    </actuator>
  </transmission>


  <transmission name="wrist_2_trans">
    <type>transmission_interface/SimpleTransmission</type>
    <joint name="wrist_2_joint">
      <hardwareInterface>PositionJointInterface</hardwareInterface>
    </joint>
    <actuator name="wrist_2_motor">
      <mechanicalReduction>1</mechanicalReduction>
    </actuator>
  </transmission>


  <transmission name="wrist_3_trans">
    <type>transmission_interface/SimpleTransmission</type>
    <joint name="wrist_3_joint">
      <hardwareInterface>PositionJointInterface</hardwareInterface>
    </joint>
    <actuator name="wrist_3_motor">
      <mechanicalReduction>1</mechanicalReduction>
    </actuator>
  </transmission>

  <!-- nothing to do here at the moment -->
  <!-- ROS base_link to UR 'Base' Coordinates transform -->
  <link name="base"/>
  <joint name="base_link-base_fixed_joint" type="fixed">
    <!-- NOTE: this rotation is only needed as long as base_link itself is
                 not corrected wrt the real robot (ie: rotated over 180
                 degrees)
      -->
    <origin rpy="0 0 -3.14159265" xyz="0 0 0"/>
    <parent link="base_link"/>
    <child link="base"/>
  </joint>

  <!-- Frame coincident with all-zeros TCP on UR controller -->
  <link name="tool0"/>
  <joint name="wrist_3_link-tool0_fixed_joint" type="fixed">
    <origin rpy="-1.570796325 0 0" xyz="0 0.0823 0"/>
    <parent link="wrist_3_link"/>
    <child link="tool0"/>
  </joint>


  <!-- ===================================================================  -->
  <!--                     CUSTOM PICKER                                    -->
  <!-- ===================================================================  -->

  <joint name="Gripper_Adapter_Fix" type="fixed">
    <parent link="ee_link0"/>
    <child link="simple_picker_pole"/>
    <origin rpy="0.0 0 0.0" xyz="0.0 0.0 0.0"/>
  </joint>


  <link name="simple_picker_pole">
    <visual>
      <origin rpy="0 1.571 0" xyz="0.3 0.0 0.0"/>
      <geometry name="pole">
        <cylinder length="0.6" radius="0.01"/>
      </geometry>
      <material name="LightGrey">
        <color rgba="0.7 0.7 0.7 1.0"/>
      </material>
    </visual>
    <collision>
      <origin rpy="0 1.571 0" xyz="0.3 0.0 0.0"/>
      <geometry name="pole">
        <cylinder length="0.6" radius="0.01"/>
      </geometry>
    </collision>
    <inertial>
      <mass value="0.1879"/>
      <inertia ixx="0.0171364731454" ixy="0.0" ixz="0.0" iyy="0.0171364731454" iyz="0.0" izz="0.033822"/>
    </inertial>
  </link>

  <joint name="joint_simple_picker_pole" type="fixed">
    <parent link="simple_picker_pole"/>
    <child link="simple_picker_tool"/>
    <origin rpy="0 3.1416 0" xyz="0.6 0.0 0.0"/>
  </joint>

  <link name="simple_picker_tool">
    <visual>
      <geometry>
        <mesh filename="package://picker/picker2.dae" scale=".33 .33 .33"/>
      </geometry>
      <material name="Grey">
        <color rgba="0.5 0.5 0.5 1.0"/>
      </material>
    </visual>
    <collision concave="yes">
      <!-- <origin rpy="0 0 0" xyz="0 0 0.015"/> -->
      <geometry>      
        <!-- <mesh filename="package://picker/picker_collision.dae" scale=".25 .25 .25"/> -->
        <mesh filename="package://picker/picker2.dae" scale=".33 .33 .33"/>
      </geometry>
    </collision>
    <inertial>
      <mass value="0.1879"/>
      <!-- <origin rpy="0 0 0" xyz="0.0 0.0 0.0"/> -->
      <inertia ixx="0.0171364731454" ixy="0.0" ixz="0.0" iyy="0.0171364731454" iyz="0.0" izz="0.033822"/>
    </inertial>
  </link>

  <joint name="ee_joint" type="fixed">
    <parent link="simple_picker_tool"/>
    <child link="ee_link"/>
    <origin rpy="0.0 0 0" xyz="-0.07 0 0"/>
  </joint>
  <link name="ee_link">
    <!-- This is in the center of the hoop -->
      <inertial>
          <mass value="0.018"/>
          <inertia ixx="8.82e-6" ixy="0" ixz="0" iyy="8.82e-6" iyz="0" izz="8.82e-6" />
      </inertial>
      <!-- DEBUG VISUAL -->
      <visual>
        <origin rpy="0 0 0" xyz="0.0 0.0 -0.005"/>
        <geometry>
          <cylinder length="0.01" radius="0.005"/>
        </geometry>
        <material name="blue">
          <color rgba="0.3 0.0 0.9 1.0"/>
        </material>
      </visual>
  </link>

<joint name="arm_camera_joint" type="fixed">
    <parent link="ee_link0"/>
    <child link="arm_camera_link"/>
    <!-- attach camera here, points at picker -->
    <origin rpy="0 -1.57 0" xyz="-0.02 0.05 0"/>
  </joint>
  <link name="arm_camera_link">
    <!-- This visual of camera -->
      <inertial>
          <mass value="0.018"/>
          <inertia ixx="8.82e-6" ixy="0" ixz="0" iyy="8.82e-6" iyz="0" izz="8.82e-6" />
      </inertial>
      <!-- DEBUG VISUAL -->
      <visual>
        <origin rpy="0 0 0" xyz="0.00 0.0 0.01"/>
        <geometry>
          <cylinder length="0.04" radius="0.02"/>
        </geometry>
        <material name="black">
          <color rgba="0.1 0.1 0.1 1.0"/>
        </material>
      </visual>
  </link>




  <joint name="base_camera_stalk_joint" type="fixed">
    <parent link="base_link"/>
    <!-- or base of stand ? -->
    <child link="base_camera_stalk"/>
    <!-- attach camera here, points at picker -->
    <origin rpy="0 3.14 0" xyz="0.00 0.00 0.2"/>
  </joint>
  <link name="base_camera_stalk">
    <!-- This visual of camera -->
      <inertial>
          <mass value="0.018"/>
          <inertia ixx="8.82e-6" ixy="0" ixz="0" iyy="8.82e-6" iyz="0" izz="8.82e-6" />
      </inertial>
      <!-- DEBUG VISUAL -->
      <visual>
        <origin rpy="0 0 0" xyz="0.00 0.0 0.01"/>
        <geometry>
          <cylinder radius="0.01" length="0.15"/>
        </geometry>
        <material name="LightGrey">
          <color rgba="0.7 0.7 0.7 1.0"/>
        </material>
      </visual>
  </link>

  <joint name="base_camera_joint" type="fixed">
    <parent link="base_camera_stalk"/>
    <!-- or base of stand ? -->
    <child link="base_camera_link"/>
    <!-- attach camera here, points at picker -->
    <origin rpy="0 0 0" xyz="0.00 0.00 -0.10"/>
  </joint>
  <link name="base_camera_link">
    <!-- This visual of camera -->
      <inertial>
          <mass value="0.018"/>
          <inertia ixx="8.82e-6" ixy="0" ixz="0" iyy="8.82e-6" iyz="0" izz="8.82e-6" />
      </inertial>
      <!-- DEBUG VISUAL -->
      <visual>
        <origin rpy="0 0 0" xyz="0.00 0.0 0.01"/>
        <geometry>
          <sphere radius="0.06"/>
        </geometry>
        <material name="black">
          <color rgba="0.1 0.1 0.1 1.0"/>
        </material>
      </visual>
  </link>
</robot>
